{
 "cells": [
  {
   "cell_type": "code",
   "execution_count": 1,
   "metadata": {},
   "outputs": [],
   "source": [
    "from collections import Counter\n",
    "import json\n",
    "import torch\n",
    "import torch.nn as nn\n",
    "from torch.utils.data import Dataset\n",
    "import torch.utils.data\n",
    "import math\n",
    "import torch.nn.functional as F"
   ]
  },
  {
   "cell_type": "code",
   "execution_count": 1,
   "metadata": {},
   "outputs": [
    {
     "name": "stderr",
     "output_type": "stream",
     "text": [
      "g:\\Software\\Anaconda\\envs\\pytorch_env\\lib\\site-packages\\tqdm\\auto.py:22: TqdmWarning: IProgress not found. Please update jupyter and ipywidgets. See https://ipywidgets.readthedocs.io/en/stable/user_install.html\n",
      "  from .autonotebook import tqdm as notebook_tqdm\n"
     ]
    }
   ],
   "source": [
    "import torch"
   ]
  },
  {
   "cell_type": "code",
   "execution_count": 2,
   "metadata": {},
   "outputs": [],
   "source": [
    "import os, sys\n",
    "currentdir = os.getcwd()\n",
    "parentdir = os.path.dirname(currentdir)\n",
    "sys.path.insert(0,parentdir)"
   ]
  },
  {
   "cell_type": "code",
   "execution_count": 3,
   "metadata": {},
   "outputs": [
    {
     "name": "stderr",
     "output_type": "stream",
     "text": [
      "g:\\Software\\Anaconda\\envs\\pytorch_env\\lib\\site-packages\\torchvision\\io\\image.py:11: UserWarning: Failed to load image Python extension: [WinError 126] The specified module could not be found\n",
      "  warn(f\"Failed to load image Python extension: {e}\")\n"
     ]
    }
   ],
   "source": [
    "from codebase.data import datamodule"
   ]
  },
  {
   "cell_type": "code",
   "execution_count": 4,
   "metadata": {},
   "outputs": [],
   "source": [
    "data1 = datamodule(None)"
   ]
  },
  {
   "cell_type": "code",
   "execution_count": 5,
   "metadata": {},
   "outputs": [],
   "source": [
    "data1.setup()"
   ]
  },
  {
   "cell_type": "code",
   "execution_count": 6,
   "metadata": {},
   "outputs": [
    {
     "name": "stdout",
     "output_type": "stream",
     "text": [
      "Text Dataset\n",
      "Num words: 18243\n",
      "Max Length: 27\n",
      "Train/val/test sizes: 177292, 22162, 22162\n",
      "Batch x stats: (torch.Size([32, 25]), torch.int64)\n",
      "Batch y stats: (torch.Size([32, 27]), torch.int64)\n",
      "\n"
     ]
    }
   ],
   "source": [
    "print(data1)"
   ]
  },
  {
   "cell_type": "code",
   "execution_count": 7,
   "metadata": {},
   "outputs": [
    {
     "name": "stdout",
     "output_type": "stream",
     "text": [
      "torch.Size([32, 25])\n",
      "torch.Size([32, 27])\n"
     ]
    }
   ],
   "source": [
    "question,reply = next(iter(data1.train_dataloader()))\n",
    "print(question.shape)\n",
    "print(reply.shape)"
   ]
  },
  {
   "cell_type": "code",
   "execution_count": 8,
   "metadata": {},
   "outputs": [],
   "source": [
    "data_config = data1.config()\n"
   ]
  },
  {
   "cell_type": "code",
   "execution_count": 9,
   "metadata": {},
   "outputs": [],
   "source": [
    "from codebase.model.transformer_model import TransformerModel\n",
    "\n",
    "model = TransformerModel(data_config)\n",
    "\n"
   ]
  },
  {
   "cell_type": "code",
   "execution_count": 10,
   "metadata": {},
   "outputs": [],
   "source": [
    "from codebase.lit_model.base import BaseLitModel"
   ]
  },
  {
   "cell_type": "code",
   "execution_count": 11,
   "metadata": {},
   "outputs": [],
   "source": [
    "lm = BaseLitModel(model,None)"
   ]
  },
  {
   "cell_type": "code",
   "execution_count": 12,
   "metadata": {},
   "outputs": [],
   "source": [
    "batch = next(iter(data1.train_dataloader()))"
   ]
  },
  {
   "cell_type": "code",
   "execution_count": 15,
   "metadata": {},
   "outputs": [
    {
     "name": "stderr",
     "output_type": "stream",
     "text": [
      "g:\\Software\\Anaconda\\envs\\pytorch_env\\lib\\site-packages\\pytorch_lightning\\core\\lightning.py:416: UserWarning: You are trying to `self.log()` but the `self.trainer` reference is not registered on the model yet. This is most likely because the model hasn't been passed to the `Trainer`\n",
      "  \"You are trying to `self.log()` but the `self.trainer` reference is not registered on the model yet.\"\n"
     ]
    },
    {
     "data": {
      "text/plain": [
       "{'loss': tensor(10.0119, grad_fn=<NllLossBackward0>)}"
      ]
     },
     "execution_count": 15,
     "metadata": {},
     "output_type": "execute_result"
    }
   ],
   "source": [
    "lm.training_step(batch,0)"
   ]
  },
  {
   "cell_type": "code",
   "execution_count": null,
   "metadata": {},
   "outputs": [],
   "source": []
  }
 ],
 "metadata": {
  "kernelspec": {
   "display_name": "Python 3",
   "language": "python",
   "name": "python3"
  },
  "language_info": {
   "codemirror_mode": {
    "name": "ipython",
    "version": 3
   },
   "file_extension": ".py",
   "mimetype": "text/x-python",
   "name": "python",
   "nbconvert_exporter": "python",
   "pygments_lexer": "ipython3",
   "version": "3.6.13"
  }
 },
 "nbformat": 4,
 "nbformat_minor": 2
}
